Workbook

Sheet Leads
A1: City | B1: CLU File No | C1: Applicant | D1: Village / Location | E1: Activity | F1: Category | G1: Area (sq m) | H1: Area (acres) | I1: Sanction Date | J1: Year | K1: Priority Score | L1: Priority Band | M1: Map (GIS) | N1: Status | O1: Owner / Contact | P1: Phone / Email | Q1: Next Step | R1: Notes
A2: Ambala | B2: CLU/AA-860A | C2: AJAY SAREEN & ANU SAREEN | D2: Mohra | E2: Motel with Banquet facility | F2: Motel | G2: 2795.7 | H2: 0.6908319 | I2: 11/03/2026 | J2: 2026 | K2: =IF($F2="Hotel",5,IF($F2="Motel",4,IF($F2="Resort",4,IF($F2="Amusement",4,IF($F2="Banquet",3,2)))))+IF($H2>=4,2,IF($H2>=2,1,0))+IF(VALUE($J2)>=2024,2,IF(VALUE($J2)>=2021,1,0)) | L2: =IF($K2>=7,"High",IF($K2>=5,"Medium","Low")) | M2: Map View | N2: New
A3: Ambala | B3: CLU/AA-806A | C3: CHANCHAL WADHAWAN | D3: Panjlass | E3: Hotel With Banquet facilities | F3: Hotel | G3: 4890.4 | H3: 1.2084431 | I3: 19/03/2025 | J3: 2025 | K3: =IF($F3="Hotel",5,IF($F3="Motel",4,IF($F3="Resort",4,IF($F3="Amusement",4,IF($F3="Banquet",3,2)))))+IF($H3>=4,2,IF($H3>=2,1,0))+IF(VALUE($J3)>=2024,2,IF(VALUE($J3)>=2021,1,0)) | L3: =IF($K3>=7,"High",IF($K3>=5,"Medium","Low")) | M3: Map View | N3: New
A4: Ambala | B4: CLU/AA-780A | C4: Ashwani | D4: Mohra | E4: Hotel With Banquet facilities | F4: Hotel | G4: 14119.7 | H4: 3.4890508 | I4: 18/10/2023 | J4: 2023 | K4: =IF($F4="Hotel",5,IF($F4="Motel",4,IF($F4="Resort",4,IF($F4="Amusement",4,IF($F4="Banquet",3,2)))))+IF($H4>=4,2,IF($H4>=2,1,0))+IF(VALUE($J4)>=2024,2,IF(VALUE($J4)>=2021,1,0)) | L4: =IF($K4>=7,"High",IF($K4>=5,"Medium","Low")) | M4: Map View | N4: Lead - verify | O4: UNVERIFIED: probable venue = Ambala Haveli, NH-44 GT Rd, village Mohra (restaurant+rooms+banquet, renovated 2020) | P4: info.ambalahaveli@gmail.com; +91 90505 66555; +91 90531 46555 | R4: Ownership link to applicant not published — confirm by phone. Src: Booking/Facebook
A5: Ambala | B5: CLU/AA-764A | C5: Ms NeKi Ram & Sons | D5: Barnala | E5: Motel with Banquet facility | F5: Motel | G5: 8239.9 | H5: 2.0361218 | I5: 06/07/2023 | J5: 2023 | K5: =IF($F5="Hotel",5,IF($F5="Motel",4,IF($F5="Resort",4,IF($F5="Amusement",4,IF($F5="Banquet",3,2)))))+IF($H5>=4,2,IF($H5>=2,1,0))+IF(VALUE($J5)>=2024,2,IF(VALUE($J5)>=2021,1,0)) | L5: =IF($K5>=7,"High",IF($K5>=5,"Medium","Low")) | M5: Map View | N5: New
A6: Ambala | B6: CLU/AA-751A | C6: LALIT KUMAR | D6: Laha | E6: Motel with Banquet facility | F6: Motel | G6: 7668.5 | H6: 1.8949259 | I6: 08/11/2023 | J6: 2023 | K6: =IF($F6="Hotel",5,IF($F6="Motel",4,IF($F6="Resort",4,IF($F6="Amusement",4,IF($F6="Banquet",3,2)))))+IF($H6>=4,2,IF($H6>=2,1,0))+IF(VALUE($J6)>=2024,2,IF(VALUE($J6)>=2021,1,0)) | L6: =IF($K6>=7,"High",IF($K6>=5,"Medium","Low")) | M6: Map View | N6: New
A7: Ambala | B7: CLU/AA-723A | C7: Smt. Sneh Jain Wo Late Sh. Pawan K. Jain | D7: Khudda Kalan | E7: Farm house | F7: Farmhouse | G7: 25 | H7: 0.0061776291 | I7: 10/05/2021 | J7: 2021 | K7: =IF($F7="Hotel",5,IF($F7="Motel",4,IF($F7="Resort",4,IF($F7="Amusement",4,IF($F7="Banquet",3,2)))))+IF($H7>=4,2,IF($H7>=2,1,0))+IF(VALUE($J7)>=2024,2,IF(VALUE($J7)>=2021,1,0)) | L7: =IF($K7>=7,"High",IF($K7>=5,"Medium","Low")) | M7: Map View | N7: New
A8: Ambala | B8: CLU/AA-674 | C8: Sh. Raminder Dang S/o Sh. Jagan Nath | D8: Village Khuda Kalan | E8: Banquet Hall | F8: Banquet | I8: 24/05/2019 | J8: 2019 | K8: =IF($F8="Hotel",5,IF($F8="Motel",4,IF($F8="Resort",4,IF($F8="Amusement",4,IF($F8="Banquet",3,2)))))+IF($H8>=4,2,IF($H8>=2,1,0))+IF(VALUE($J8)>=2024,2,IF(VALUE($J8)>=2021,1,0)) | L8: =IF($K8>=7,"High",IF($K8>=5,"Medium","Low")) | M8: Map View | N8: New
A9: Ambala | B9: CLU/AA-657 | C9: Sh. Hartej Singh S/o Sh. Twinderjit Singh & others | D9: Ambala Cantt. | E9: Amusement Park/ Restaurant | F9: Amusement | I9: 19/04/2018 | J9: 2018 | K9: =IF($F9="Hotel",5,IF($F9="Motel",4,IF($F9="Resort",4,IF($F9="Amusement",4,IF($F9="Banquet",3,2)))))+IF($H9>=4,2,IF($H9>=2,1,0))+IF(VALUE($J9)>=2024,2,IF(VALUE($J9)>=2021,1,0)) | L9: =IF($K9>=7,"High",IF($K9>=5,"Medium","Low")) | M9: Map View | N9: New
A10: Ambala | B10: CLU/AA-618 | C10: Sh. Jasmer Singh, Sh. Parminder Singh, Sh. Gurdev Singh, Sh. Sukhchain Singh, Smt. Balwinder Kaur, Sh. Gagandeep Singh-Gurkirat Singh, Smt. Tejinder Kaur (Earlier in the name of Sh. Harbans Singh S/o Sh. Kartar Singh) | D10: Ambala | E10: Farmhouse | F10: Farmhouse | I10: 01/03/2017 | J10: 2017 | K10: =IF($F10="Hotel",5,IF($F10="Motel",4,IF($F10="Resort",4,IF($F10="Amusement",4,IF($F10="Banquet",3,2)))))+IF($H10>=4,2,IF($H10>=2,1,0))+IF(VALUE($J10)>=2024,2,IF(VALUE($J10)>=2021,1,0)) | L10: =IF($K10>=7,"High",IF($K10>=5,"Medium","Low")) | M10: Map View | N10: New
A11: Ambala | B11: CLU/AA-643 | C11: Sh. Naresh Kapoor S/o Sh. Madan Lal Kapoor C/o Kapoor Handloom Industries | D11: Ambala | E11: Banquet Hall | F11: Banquet | I11: 19/06/2017 | J11: 2017 | K11: =IF($F11="Hotel",5,IF($F11="Motel",4,IF($F11="Resort",4,IF($F11="Amusement",4,IF($F11="Banquet",3,2)))))+IF($H11>=4,2,IF($H11>=2,1,0))+IF(VALUE($J11)>=2024,2,IF(VALUE($J11)>=2021,1,0)) | L11: =IF($K11>=7,"High",IF($K11>=5,"Medium","Low")) | M11: Map View | N11: New
A12: Ambala | B12: CLU/AA-652 | C12: Sh. Hartej Singh S/o Sh. Inderjeet Singh, Sh. Tawinderjeet Singh S/o Sh. Daya Singh, Smt. Gurpreet Kaur W/o Sh. Tawinderjeet Singh | D12: Ambala | E12: Amusement Park and Food Court (Recreational Centre) | F12: Amusement | I12: 28/11/2017 | J12: 2017 | K12: =IF($F12="Hotel",5,IF($F12="Motel",4,IF($F12="Resort",4,IF($F12="Amusement",4,IF($F12="Banquet",3,2)))))+IF($H12>=4,2,IF($H12>=2,1,0))+IF(VALUE($J12)>=2024,2,IF(VALUE($J12)>=2021,1,0)) | L12: =IF($K12>=7,"High",IF($K12>=5,"Medium","Low")) | M12: Map View | N12: New
A13: Hisar | B13: CLU/HR-1368A | C13: Raj Kumar | D13: Satrod khas | E13: Hotel-cum-Resort | F13: Hotel | G13: 26810.2 | H13: 6.6249388 | I13: 13/04/2026 | J13: 2026 | K13: =IF($F13="Hotel",5,IF($F13="Motel",4,IF($F13="Resort",4,IF($F13="Amusement",4,IF($F13="Banquet",3,2)))))+IF($H13>=4,2,IF($H13>=2,1,0))+IF(VALUE($J13)>=2024,2,IF(VALUE($J13)>=2021,1,0)) | L13: =IF($K13>=7,"High",IF($K13>=5,"Medium","Low")) | M13: Map View | N13: New
A14: Hisar | B14: CLU/HR-1391A | C14: Ved Parkash And Smt. Aarti Sardana | D14: Kaimri | E14: Farm house | F14: Farmhouse | G14: 6045 | H14: 1.4937507 | I14: 03/07/2026 | J14: 2026 | K14: =IF($F14="Hotel",5,IF($F14="Motel",4,IF($F14="Resort",4,IF($F14="Amusement",4,IF($F14="Banquet",3,2)))))+IF($H14>=4,2,IF($H14>=2,1,0))+IF(VALUE($J14)>=2024,2,IF(VALUE($J14)>=2021,1,0)) | L14: =IF($K14>=7,"High",IF($K14>=5,"Medium","Low")) | M14: Map View | N14: New
A15: Hisar | B15: CLU/HR-1415A | C15: Om Pati Kusum Modi Seema Modi Renu Modi | D15: Mayar | E15: Hotel With Banquet facilities | F15: Hotel | G15: 5720.5 | H15: 1.4135651 | I15: 28/07/2026 | J15: 2026 | K15: =IF($F15="Hotel",5,IF($F15="Motel",4,IF($F15="Resort",4,IF($F15="Amusement",4,IF($F15="Banquet",3,2)))))+IF($H15>=4,2,IF($H15>=2,1,0))+IF(VALUE($J15)>=2024,2,IF(VALUE($J15)>=2021,1,0)) | L15: =IF($K15>=7,"High",IF($K15>=5,"Medium","Low")) | M15: Map View | N15: New
A16: Hisar | B16: CLU/HR-1398A | C16: veena rani and deepak kumar | D16: Prabhuwala | E16: Motel with Banquet facility | F16: Motel | G16: 2697.3 | H16: 0.66651676 | I16: 09/06/2026 | J16: 2026 | K16: =IF($F16="Hotel",5,IF($F16="Motel",4,IF($F16="Resort",4,IF($F16="Amusement",4,IF($F16="Banquet",3,2)))))+IF($H16>=4,2,IF($H16>=2,1,0))+IF(VALUE($J16)>=2024,2,IF(VALUE($J16)>=2021,1,0)) | L16: =IF($K16>=7,"High",IF($K16>=5,"Medium","Low")) | M16: Map View | N16: New
A17: Hisar | B17: CLU/HR-1388A | C17: Jagdish | D17: Gaibipur | E17: Motel with Banquet facility | F17: Motel | G17: 2018.6 | H17: 0.49880648 | I17: 05/03/2026 | J17: 2026 | K17: =IF($F17="Hotel",5,IF($F17="Motel",4,IF($F17="Resort",4,IF($F17="Amusement",4,IF($F17="Banquet",3,2)))))+IF($H17>=4,2,IF($H17>=2,1,0))+IF(VALUE($J17)>=2024,2,IF(VALUE($J17)>=2021,1,0)) | L17: =IF($K17>=7,"High",IF($K17>=5,"Medium","Low")) | M17: Map View | N17: New
A18: Hisar | B18: CLU/HR-1350A | C18: Anil Kumar | D18: Raipur | E18: Farm house | F18: Farmhouse | G18: 7309.6 | H18: 1.8062399 | I18: 01/10/2025 | J18: 2025 | K18: =IF($F18="Hotel",5,IF($F18="Motel",4,IF($F18="Resort",4,IF($F18="Amusement",4,IF($F18="Banquet",3,2)))))+IF($H18>=4,2,IF($H18>=2,1,0))+IF(VALUE($J18)>=2024,2,IF(VALUE($J18)>=2021,1,0)) | L18: =IF($K18>=7,"High",IF($K18>=5,"Medium","Low")) | M18: Map View | N18: New
A19: Hisar | B19: CLU/HR-1352A | C19: Parveen and Pormila | D19: Sarsod | E19: Hotel With Banquet facilities | F19: Hotel | G19: 6097 | H19: 1.5066002 | I19: 20/11/2025 | J19: 2025 | K19: =IF($F19="Hotel",5,IF($F19="Motel",4,IF($F19="Resort",4,IF($F19="Amusement",4,IF($F19="Banquet",3,2)))))+IF($H19>=4,2,IF($H19>=2,1,0))+IF(VALUE($J19)>=2024,2,IF(VALUE($J19)>=2021,1,0)) | L19: =IF($K19>=7,"High",IF($K19>=5,"Medium","Low")) | M19: Map View | N19: New
A20: Hisar | B20: CLU/HR-1309A | C20: Niti Garg & others | D20: Chickenwas | E20: Farm house | F20: Farmhouse | G20: 5674.2 | H20: 1.4021241 | I20: 21/04/2025 | J20: 2025 | K20: =IF($F20="Hotel",5,IF($F20="Motel",4,IF($F20="Resort",4,IF($F20="Amusement",4,IF($F20="Banquet",3,2)))))+IF($H20>=4,2,IF($H20>=2,1,0))+IF(VALUE($J20)>=2024,2,IF(VALUE($J20)>=2021,1,0)) | L20: =IF($K20>=7,"High",IF($K20>=5,"Medium","Low")) | M20: Map View | N20: New
A21: Hisar | B21: CLU/HR-1282A | C21: Sunil Kumar | D21: Mayar | E21: Motel with Banquet facility | F21: Motel | G21: 2001.3 | H21: 0.49453156 | I21: 10/11/2025 | J21: 2025 | K21: =IF($F21="Hotel",5,IF($F21="Motel",4,IF($F21="Resort",4,IF($F21="Amusement",4,IF($F21="Banquet",3,2)))))+IF($H21>=4,2,IF($H21>=2,1,0))+IF(VALUE($J21)>=2024,2,IF(VALUE($J21)>=2021,1,0)) | L21: =IF($K21>=7,"High",IF($K21>=5,"Medium","Low")) | M21: Map View | N21: New
A22: Hisar | B22: CLU/HR-1279A | C22: Uhsa Rani | D22: Barwala | E22: Motel with Banquet facility | F22: Motel | G22: 1998.1 | H22: 0.49374083 | I22: 10/03/2025 | J22: 2025 | K22: =IF($F22="Hotel",5,IF($F22="Motel",4,IF($F22="Resort",4,IF($F22="Amusement",4,IF($F22="Banquet",3,2)))))+IF($H22>=4,2,IF($H22>=2,1,0))+IF(VALUE($J22)>=2024,2,IF(VALUE($J22)>=2021,1,0)) | L22: =IF($K22>=7,"High",IF($K22>=5,"Medium","Low")) | M22: Map View | N22: New
A23: Hisar | B23: CLU/HR-1248A | C23: RAJPAL & SURENDER SONS OF SADHU RAM | D23: Quatabpur | E23: Motel without Banquet Facility | F23: Motel | G23: 6520.6 | H23: 1.6112739 | I23: 25/01/2024 | J23: 2024 | K23: =IF($F23="Hotel",5,IF($F23="Motel",4,IF($F23="Resort",4,IF($F23="Amusement",4,IF($F23="Banquet",3,2)))))+IF($H23>=4,2,IF($H23>=2,1,0))+IF(VALUE($J23)>=2024,2,IF(VALUE($J23)>=2021,1,0)) | L23: =IF($K23>=7,"High",IF($K23>=5,"Medium","Low")) | M23: Map View | N23: New
A24: Hisar | B24: CLU/HR-1260A | C24: SH SIDHARATH | D24: Narnaund | E24: Motel with Banquet facility | F24: Motel | G24: 5863.4 | H24: 1.4488764 | I24: 26/07/2024 | J24: 2024 | K24: =IF($F24="Hotel",5,IF($F24="Motel",4,IF($F24="Resort",4,IF($F24="Amusement",4,IF($F24="Banquet",3,2)))))+IF($H24>=4,2,IF($H24>=2,1,0))+IF(VALUE($J24)>=2024,2,IF(VALUE($J24)>=2021,1,0)) | L24: =IF($K24>=7,"High",IF($K24>=5,"Medium","Low")) | M24: Map View | N24: New
... A38: Hisar | B38: CLU/HR-954A | C38: Ramandeep Kaur | D38: Chickenwas | E38: Motel with Banquet facility | F38: Motel | G38: 2355.2 | H38: 0.58198208 | I38: 17/03/2022 | J38: 2022 | K38: =IF($F38="Hotel",5,IF($F38="Motel",4,IF($F38="Resort",4,IF($F38="Amusement",4,IF($F38="Banquet",3,2)))))+IF($H38>=4,2,IF($H38>=2,1,0))+IF(VALUE($J38)>=2024,2,IF(VALUE($J38)>=2021,1,0)) | L38: =IF($K38>=7,"High",IF($K38>=5,"Medium","Low")) | M38: Map View | N38: New
A39: Hisar | B39: CLU/HR-1155A | C39: GREEN VALLEY | D39: Quatabpur | E39: Motel with Banquet facility | F39: Motel | G39: 20198.3 | H39: 4.9911042 | I39: 06/12/2021 | J39: 2021 | K39: =IF($F39="Hotel",5,IF($F39="Motel",4,IF($F39="Resort",4,IF($F39="Amusement",4,IF($F39="Banquet",3,2)))))+IF($H39>=4,2,IF($H39>=2,1,0))+IF(VALUE($J39)>=2024,2,IF(VALUE($J39)>=2021,1,0)) | L39: =IF($K39>=7,"High",IF($K39>=5,"Medium","Low")) | M39: Map View | N39: Contact found | O39: Green Valley (regd. partnership, GSTIN 06AAWFG6114H1Z7), GT Rd Kutabpur, Hansi — operating leisure complex | P39: greenvalliewaterpark@gmail.com; +91 98121 57357; +91 77000 12262 | R39: Operating: Green Vallie Water Park (2025), Haldiram's, Levi's store, banquets on NH-9. Src: greenvalliewaterpark.com + LEI/GST
A40: Hisar | B40: CLU/HR-1134A | C40: Sh.Sajjan Gupta Sh.Sahil Goyal Etc. | D40: Quatabpur | E40: Motel with Banquet facility | F40: Motel | G40: 16843.7 | H40: 4.1621652 | I40: 25/06/2021 | J40: 2021 | K40: =IF($F40="Hotel",5,IF($F40="Motel",4,IF($F40="Resort",4,IF($F40="Amusement",4,IF($F40="Banquet",3,2)))))+IF($H40>=4,2,IF($H40>=2,1,0))+IF(VALUE($J40)>=2024,2,IF(VALUE($J40)>=2021,1,0)) | L40: =IF($K40>=7,"High",IF($K40>=5,"Medium","Low")) | M40: Map View | N40: New
A41: Hisar | B41: CLU/HR-831 | C41: Smt. Usha Kataria W/o Sh. Kewal Kumar Kataria | D41: Village Khedar | E41: Motel without Banquet Hall | F41: Motel | I41: 11/06/2019 | J41: 2019 | K41: =IF($F41="Hotel",5,IF($F41="Motel",4,IF($F41="Resort",4,IF($F41="Amusement",4,IF($F41="Banquet",3,2)))))+IF($H41>=4,2,IF($H41>=2,1,0))+IF(VALUE($J41)>=2024,2,IF(VALUE($J41)>=2021,1,0)) | L41: =IF($K41>=7,"High",IF($K41>=5,"Medium","Low")) | M41: Map View | N41: New
A42: Hisar | B42: CLU/HR-902 | C42: Smt. Hem Lata W/o Sh. Sunil | D42: Village Hansi | E42: Motel without Banquet Hall | F42: Motel | I42: 06/08/2019 | J42: 2019 | K42: =IF($F42="Hotel",5,IF($F42="Motel",4,IF($F42="Resort",4,IF($F42="Amusement",4,IF($F42="Banquet",3,2)))))+IF($H42>=4,2,IF($H42>=2,1,0))+IF(VALUE($J42)>=2024,2,IF(VALUE($J42)>=2021,1,0)) | L42: =IF($K42>=7,"High",IF($K42>=5,"Medium","Low")) | M42: Map View | N42: New
A43: Hisar | B43: CLU/HR-842 | C43: Smt. Sheela Devi W/o Sh. Rammehar | D43: Hansi | E43: Motel without Banquet Facility | F43: Motel | I43: 27/04/2018 | J43: 2018 | K43: =IF($F43="Hotel",5,IF($F43="Motel",4,IF($F43="Resort",4,IF($F43="Amusement",4,IF($F43="Banquet",3,2)))))+IF($H43>=4,2,IF($H43>=2,1,0))+IF(VALUE($J43)>=2024,2,IF(VALUE($J43)>=2021,1,0)) | L43: =IF($K43>=7,"High",IF($K43>=5,"Medium","Low")) | M43: Map View | N43: New
A44: Hisar | B44: CLU/HR-851 | C44: Ms. Bimla Devi D/o Sh. Surjan Dass | D44: Barwala | E44: Motel without Banquet Facility | F44: Motel | I44: 07/03/2018 | J44: 2018 | K44: =IF($F44="Hotel",5,IF($F44="Motel",4,IF($F44="Resort",4,IF($F44="Amusement",4,IF($F44="Banquet",3,2)))))+IF($H44>=4,2,IF($H44>=2,1,0))+IF(VALUE($J44)>=2024,2,IF(VALUE($J44)>=2021,1,0)) | L44: =IF($K44>=7,"High",IF($K44>=5,"Medium","Low")) | M44: Map View | N44: New
A45: Karnal | B45: CLU/KL-1369A | C45: RAJESH, RAJEEV, AMIT GOYAL | D45: Shamgarh | E45: Hotel With Banquet facilities | F45: Hotel | G45: 8566.06 | H45: 2.1167177 | I45: 02/03/2026 | J45: 2026 | K45: =IF($F45="Hotel",5,IF($F45="Motel",4,IF($F45="Resort",4,IF($F45="Amusement",4,IF($F45="Banquet",3,2)))))+IF($H45>=4,2,IF($H45>=2,1,0))+IF(VALUE($J45)>=2024,2,IF(VALUE($J45)>=2021,1,0)) | L45: =IF($K45>=7,"High",IF($K45>=5,"Medium","Low")) | M45: Map View | N45: New | R45: Shamgarh GT-Road belt (comparables: The Vivaan, Comfort Inn Taraori). No footprint — gatekeeper/DTCP-file ID.
A46: Karnal | B46: CLU/KL-1245A | C46: SMT. SUDESH RAWAL | D46: Barna | E46: Motel cum Restaurant | F46: Motel | G46: 6885.42 | H46: 1.7014228 | I46: 20/02/2026 | J46: 2026 | K46: =IF($F46="Hotel",5,IF($F46="Motel",4,IF($F46="Resort",4,IF($F46="Amusement",4,IF($F46="Banquet",3,2)))))+IF($H46>=4,2,IF($H46>=2,1,0))+IF(VALUE($J46)>=2024,2,IF(VALUE($J46)>=2021,1,0)) | L46: =IF($K46>=7,"High",IF($K46>=5,"Medium","Low")) | M46: Map View | N46: New
A47: Karnal | B47: CLU/KL-1392A | C47: Arpit Goyal and Sanchit Goyal | D47: Samana bahu | E47: Motel with Banquet facility | F47: Motel | G47: 4870.61 | H47: 1.2035529 | I47: 13/04/2026 | J47: 2026 | K47: =IF($F47="Hotel",5,IF($F47="Motel",4,IF($F47="Resort",4,IF($F47="Amusement",4,IF($F47="Banquet",3,2)))))+IF($H47>=4,2,IF($H47>=2,1,0))+IF(VALUE($J47)>=2024,2,IF(VALUE($J47)>=2021,1,0)) | L47: =IF($K47>=7,"High",IF($K47>=5,"Medium","Low")) | M47: Map View | N47: New
A48: Karnal | B48: CLU/KL-1400A | C48: Om Parkash | D48: Kond | E48: Non Star Hotel | F48: Hotel | G48: 4472.7 | H48: 1.1052273 | I48: 17/03/2026 | J48: 2026 | K48: =IF($F48="Hotel",5,IF($F48="Motel",4,IF($F48="Resort",4,IF($F48="Amusement",4,IF($F48="Banquet",3,2)))))+IF($H48>=4,2,IF($H48>=2,1,0))+IF(VALUE($J48)>=2024,2,IF(VALUE($J48)>=2021,1,0)) | L48: =IF($K48>=7,"High",IF($K48>=5,"Medium","Low")) | M48: Map View | N48: New
A49: Karnal | B49: CLU/KL-1324A | C49: DESHRAJ SON OF SADHU RAM | D49: Shamgarh | E49: Banquet Hall | F49: Banquet | G49: 24236.5 | H49: 5.9889643 | I49: 26/05/2025 | J49: 2025 | K49: =IF($F49="Hotel",5,IF($F49="Motel",4,IF($F49="Resort",4,IF($F49="Amusement",4,IF($F49="Banquet",3,2)))))+IF($H49>=4,2,IF($H49>=2,1,0))+IF(VALUE($J49)>=2024,2,IF(VALUE($J49)>=2021,1,0)) | L49: =IF($K49>=7,"High",IF($K49>=5,"Medium","Low")) | M49: Map View | N49: New
A50: Karnal | B50: CLU/KL-1263A | C50: SUKHVINDER KAUR | D50: SALARU | E50: Banquet Hall | F50: Banquet | G50: 8101.7 | H50: 2.0019719 | I50: 17/03/2025 | J50: 2025 | K50: =IF($F50="Hotel",5,IF($F50="Motel",4,IF($F50="Resort",4,IF($F50="Amusement",4,IF($F50="Banquet",3,2)))))+IF($H50>=4,2,IF($H50>=2,1,0))+IF(VALUE($J50)>=2024,2,IF(VALUE($J50)>=2021,1,0)) | L50: =IF($K50>=7,"High",IF($K50>=5,"Medium","Low")) | M50: Map View | N50: New
A51: Karnal | B51: CLU/KL-951C | C51: NARAIN DASS RAHEA | D51: Nawal | E51: Motel without Banquet Facility | F51: Motel | G51: 1214.05 | H51: 0.29999802 | I51: 03/05/2025 | J51: 2025 | K51: =IF($F51="Hotel",5,IF($F51="Motel",4,IF($F51="Resort",4,IF($F51="Amusement",4,IF($F51="Banquet",3,2)))))+IF($H51>=4,2,IF($H51>=2,1,0))+IF(VALUE($J51)>=2024,2,IF(VALUE($J51)>=2021,1,0)) | L51: =IF($K51>=7,"High",IF($K51>=5,"Medium","Low")) | M51: Map View | N51: New
A52: Karnal | B52: CLU/KL-1302A | C52: Deventure Hotels | D52: Basdhara | E52: Hotel With Banquet facilities | F52: Hotel | G52: 19967.7 | H52: 4.9341218 | I52: 28/10/2024 | J52: 2024 | K52: =IF($F52="Hotel",5,IF($F52="Motel",4,IF($F52="Resort",4,IF($F52="Amusement",4,IF($F52="Banquet",3,2)))))+IF($H52>=4,2,IF($H52>=2,1,0))+IF(VALUE($J52)>=2024,2,IF(VALUE($J52)>=2021,1,0)) | L52: =IF($K52>=7,"High",IF($K52>=5,"Medium","Low")) | M52: Map View | N52: Contact found | O52: Rajeev Mukul — Founder & MD, Deventure Hotel and Resorts P.L. (CIN U55101DL2010PTC205366) | P52: saleshead@deventurehotel.com; gm.karnal@deventurehotel.com; +91 93178 88989; 0184-3540400 | R52: Operating chain (Karnal NH-44, Shimla Hills, Delhi x2, Sarovar Portico Kapashera). Basdhara CLU = highway-resort expansion, unannounced. Src: deventurehotel.com + ZaubaCorp
A53: Karnal | B53: CLU/KL-1247A | C53: MANU CHAWLA | D53: Kurtail | E53: Banquet Hall | F53: Banquet | G53: 14540 | H53: 3.5929091 | I53: 28/06/2024 | J53: 2024 | K53: =IF($F53="Hotel",5,IF($F53="Motel",4,IF($F53="Resort",4,IF($F53="Amusement",4,IF($F53="Banquet",3,2)))))+IF($H53>=4,2,IF($H53>=2,1,0))+IF(VALUE($J53)>=2024,2,IF(VALUE($J53)>=2021,1,0)) | L53: =IF($K53>=7,"High",IF($K53>=5,"Medium","Low")) | M53: Map View | N53: New
...

Sheet Summary
A1: Hospitality CLU Leads — Summary
A2: All figures computed live from the Leads sheet (COUNTIFS/SUMIFS).
A4: City | B4: Leads | C4: Acres | D4: Hotel | E4: Motel | F4: Resort | G4: Banquet | H4: Farmhouse | I4: Amusement | J4: Club | K4: High priority
A5: Karnal | B5: =COUNTIF(Leads!$A$2:$A$141,$A5) | C5: =SUMIF(Leads!$A$2:$A$141,$A5,Leads!$H$2:$H$141) | D5: =COUNTIFS(Leads!$A$2:$A$141,$A5,Leads!$F$2:$F$141,"Hotel") | E5: =COUNTIFS(Leads!$A$2:$A$141,$A5,Leads!$F$2:$F$141,"Motel") | F5: =COUNTIFS(Leads!$A$2:$A$141,$A5,Leads!$F$2:$F$141,"Resort") | G5: =COUNTIFS(Leads!$A$2:$A$141,$A5,Leads!$F$2:$F$141,"Banquet") | H5: =COUNTIFS(Leads!$A$2:$A$141,$A5,Leads!$F$2:$F$141,"Farmhouse") | I5: =COUNTIFS(Leads!$A$2:$A$141,$A5,Leads!$F$2:$F$141,"Amusement") | J5: =COUNTIFS(Leads!$A$2:$A$141,$A5,Leads!$F$2:$F$141,"Club") | K5: =COUNTIFS(Leads!$A$2:$A$141,$A5,Leads!$L$2:$L$141,"High")
A6: Panipat | B6: =COUNTIF(Leads!$A$2:$A$141,$A6) | C6: =SUMIF(Leads!$A$2:$A$141,$A6,Leads!$H$2:$H$141) | D6: =COUNTIFS(Leads!$A$2:$A$141,$A6,Leads!$F$2:$F$141,"Hotel") | E6: =COUNTIFS(Leads!$A$2:$A$141,$A6,Leads!$F$2:$F$141,"Motel") | F6: =COUNTIFS(Leads!$A$2:$A$141,$A6,Leads!$F$2:$F$141,"Resort") | G6: =COUNTIFS(Leads!$A$2:$A$141,$A6,Leads!$F$2:$F$141,"Banquet") | H6: =COUNTIFS(Leads!$A$2:$A$141,$A6,Leads!$F$2:$F$141,"Farmhouse") | I6: =COUNTIFS(Leads!$A$2:$A$141,$A6,Leads!$F$2:$F$141,"Amusement") | J6: =COUNTIFS(Leads!$A$2:$A$141,$A6,Leads!$F$2:$F$141,"Club") | K6: =COUNTIFS(Leads!$A$2:$A$141,$A6,Leads!$L$2:$L$141,"High")
A7: Sonipat | B7: =COUNTIF(Leads!$A$2:$A$141,$A7) | C7: =SUMIF(Leads!$A$2:$A$141,$A7,Leads!$H$2:$H$141) | D7: =COUNTIFS(Leads!$A$2:$A$141,$A7,Leads!$F$2:$F$141,"Hotel") | E7: =COUNTIFS(Leads!$A$2:$A$141,$A7,Leads!$F$2:$F$141,"Motel") | F7: =COUNTIFS(Leads!$A$2:$A$141,$A7,Leads!$F$2:$F$141,"Resort") | G7: =COUNTIFS(Leads!$A$2:$A$141,$A7,Leads!$F$2:$F$141,"Banquet") | H7: =COUNTIFS(Leads!$A$2:$A$141,$A7,Leads!$F$2:$F$141,"Farmhouse") | I7: =COUNTIFS(Leads!$A$2:$A$141,$A7,Leads!$F$2:$F$141,"Amusement") | J7: =COUNTIFS(Leads!$A$2:$A$141,$A7,Leads!$F$2:$F$141,"Club") | K7: =COUNTIFS(Leads!$A$2:$A$141,$A7,Leads!$L$2:$L$141,"High")
A8: Rohtak | B8: =COUNTIF(Leads!$A$2:$A$141,$A8) | C8: =SUMIF(Leads!$A$2:$A$141,$A8,Leads!$H$2:$H$141) | D8: =COUNTIFS(Leads!$A$2:$A$141,$A8,Leads!$F$2:$F$141,"Hotel") | E8: =COUNTIFS(Leads!$A$2:$A$141,$A8,Leads!$F$2:$F$141,"Motel") | F8: =COUNTIFS(Leads!$A$2:$A$141,$A8,Leads!$F$2:$F$141,"Resort") | G8: =COUNTIFS(Leads!$A$2:$A$141,$A8,Leads!$F$2:$F$141,"Banquet") | H8: =COUNTIFS(Leads!$A$2:$A$141,$A8,Leads!$F$2:$F$141,"Farmhouse") | I8: =COUNTIFS(Leads!$A$2:$A$141,$A8,Leads!$F$2:$F$141,"Amusement") | J8: =COUNTIFS(Leads!$A$2:$A$141,$A8,Leads!$F$2:$F$141,"Club") | K8: =COUNTIFS(Leads!$A$2:$A$141,$A8,Leads!$L$2:$L$141,"High")
A9: Hisar | B9: =COUNTIF(Leads!$A$2:$A$141,$A9) | C9: =SUMIF(Leads!$A$2:$A$141,$A9,Leads!$H$2:$H$141) | D9: =COUNTIFS(Leads!$A$2:$A$141,$A9,Leads!$F$2:$F$141,"Hotel") | E9: =COUNTIFS(Leads!$A$2:$A$141,$A9,Leads!$F$2:$F$141,"Motel") | F9: =COUNTIFS(Leads!$A$2:$A$141,$A9,Leads!$F$2:$F$141,"Resort") | G9: =COUNTIFS(Leads!$A$2:$A$141,$A9,Leads!$F$2:$F$141,"Banquet") | H9: =COUNTIFS(Leads!$A$2:$A$141,$A9,Leads!$F$2:$F$141,"Farmhouse") | I9: =COUNTIFS(Leads!$A$2:$A$141,$A9,Leads!$F$2:$F$141,"Amusement") | J9: =COUNTIFS(Leads!$A$2:$A$141,$A9,Leads!$F$2:$F$141,"Club") | K9: =COUNTIFS(Leads!$A$2:$A$141,$A9,Leads!$L$2:$L$141,"High")
A10: Ambala | B10: =COUNTIF(Leads!$A$2:$A$141,$A10) | C10: =SUMIF(Leads!$A$2:$A$141,$A10,Leads!$H$2:$H$141) | D10: =COUNTIFS(Leads!$A$2:$A$141,$A10,Leads!$F$2:$F$141,"Hotel") | E10: =COUNTIFS(Leads!$A$2:$A$141,$A10,Leads!$F$2:$F$141,"Motel") | F10: =COUNTIFS(Leads!$A$2:$A$141,$A10,Leads!$F$2:$F$141,"Resort") | G10: =COUNTIFS(Leads!$A$2:$A$141,$A10,Leads!$F$2:$F$141,"Banquet") | H10: =COUNTIFS(Leads!$A$2:$A$141,$A10,Leads!$F$2:$F$141,"Farmhouse") | I10: =COUNTIFS(Leads!$A$2:$A$141,$A10,Leads!$F$2:$F$141,"Amusement") | J10: =COUNTIFS(Leads!$A$2:$A$141,$A10,Leads!$F$2:$F$141,"Club") | K10: =COUNTIFS(Leads!$A$2:$A$141,$A10,Leads!$L$2:$L$141,"High")
A11: Kurukshetra | B11: =COUNTIF(Leads!$A$2:$A$141,$A11) | C11: =SUMIF(Leads!$A$2:$A$141,$A11,Leads!$H$2:$H$141) | D11: =COUNTIFS(Leads!$A$2:$A$141,$A11,Leads!$F$2:$F$141,"Hotel") | E11: =COUNTIFS(Leads!$A$2:$A$141,$A11,Leads!$F$2:$F$141,"Motel") | F11: =COUNTIFS(Leads!$A$2:$A$141,$A11,Leads!$F$2:$F$141,"Resort") | G11: =COUNTIFS(Leads!$A$2:$A$141,$A11,Leads!$F$2:$F$141,"Banquet") | H11: =COUNTIFS(Leads!$A$2:$A$141,$A11,Leads!$F$2:$F$141,"Farmhouse") | I11: =COUNTIFS(Leads!$A$2:$A$141,$A11,Leads!$F$2:$F$141,"Amusement") | J11: =COUNTIFS(Leads!$A$2:$A$141,$A11,Leads!$F$2:$F$141,"Club") | K11: =COUNTIFS(Leads!$A$2:$A$141,$A11,Leads!$L$2:$L$141,"High")
A12: Total | B12: =SUM(B5:B11) | C12: =SUM(C5:C11) | D12: =SUM(D5:D11) | E12: =SUM(E5:E11) | F12: =SUM(F5:F11) | G12: =SUM(G5:G11) | H12: =SUM(H5:H11) | I12: =SUM(I5:I11) | ... K12: =SUM(K5:K11)
A15: How to use this file
A16: Yellow-header columns on the Leads sheet (Status, Owner/Contact, Phone/Email, Next Step, Notes) are yours to fill in; every other column is source data — do not edit.
A17: Status values suggested: New / Researching / Contacted / Meeting / Dead. Example: Status=Contacted, Owner=Deventure Hotels front office, Phone=via site visit, Next Step=Site meeting w/ Taran, Notes=open to flag talks.
A18: Priority Score (col K) = category weight (Hotel 5, Motel/Resort/Amusement 4, Banquet 3, Farmhouse/Club 2) + size bonus (>=4 ac +2, >=2 ac +1) + recency (2024+ +2, 2021+ +1). Band: High >=7, Medium 5-6, Low <5. Assumption made by Caspar analysis, not from any external source.
A19: Map (GIS) links open the parcel's boundary on DTCP Haryana's official map (tcpharyana.gov.in).
A20: Source: DTCP Haryana CLU year-registers 2017-2026 (tcpharyana.gov.in/WebAdmin/clu/index?id=YYYY), scraped Aug 13, 2026, filtered to hotel/motel/resort/banquet/farmhouse/amusement/club activities.
